5:return {{["y"] = 3, ["x"] = 0, ["name"] = "default:dirt", ["z"] = 3}, {["y"] = 4, ["x"] = 0, ["name"] = "default:dirt_with_grass", ["z"] = 1}, {["y"] = 4, ["x"] = 0, ["name"] = "default:dirt_with_grass", ["z"] = 2}, {["y"] = 4, ["x"] = 0, ["name"] = "default:dirt_with_grass", ["z"] = 3}, {["y"] = 4, ["x"] = 0, ["name"] = "default:dirt_with_grass", ["z"] = 4}, {["y"] = 4, ["x"] = 0, ["name"] = "default:dirt_with_grass", ["z"] = 5}, {["y"] = 2, ["x"] = 1, ["name"] = "default:dirt", ["z"] = 3}, {["y"] = 3, ["x"] = 1, ["name"] = "default:dirt", ["z"] = 1}, {["y"] = 3, ["x"] = 1, ["name"] = "default:dirt", ["z"] = 2}, {["y"] = 3, ["x"] = 1, ["name"] = "default:dirt", ["z"] = 3}, {["y"] = 3, ["x"] = 1, ["name"] = "default:dirt", ["z"] = 4}, {["y"] = 3, ["x"] = 1, ["name"] = "default:dirt", ["z"] = 5}, {["y"] = 4, ["x"] = 1, ["name"] = "default:dirt_with_grass", ["z"] = 0}, {["y"] = 4, ["x"] = 1, ["name"] = "default:dirt_with_grass", ["z"] = 1}, {["y"] = 4, ["x"] = 1, ["name"] = "default:dirt_with_grass", ["z"] = 2}, {["y"] = 4, ["x"] = 1, ["name"] = "default:dirt_with_grass", ["z"] = 3}, {["y"] = 4, ["x"] = 1, ["name"] = "default:dirt_with_grass", ["z"] = 4}, {["y"] = 4, ["x"] = 1, ["name"] = "default:dirt_with_grass", ["z"] = 5}, {["y"] = 4, ["x"] = 1, ["name"] = "default:dirt_with_grass", ["z"] = 6}, {["y"] = 9, ["x"] = 1, ["name"] = "default:leaves", ["z"] = 1, ["param1"] = 14}, {["y"] = 9, ["x"] = 1, ["name"] = "default:leaves", ["z"] = 2, ["param1"] = 14}, {["y"] = 9, ["x"] = 1, ["name"] = "default:leaves", ["z"] = 3, ["param1"] = 14}, {["y"] = 9, ["x"] = 1, ["name"] = "default:leaves", ["z"] = 4, ["param1"] = 14}, {["y"] = 10, ["x"] = 1, ["name"] = "default:leaves", ["z"] = 1, ["param1"] = 14}, {["y"] = 10, ["x"] = 1, ["name"] = "default:leaves", ["z"] = 2, ["param1"] = 14}, {["y"] = 10, ["x"] = 1, ["name"] = "default:leaves", ["z"] = 3, ["param1"] = 14}, {["y"] = 10, ["x"] = 1, ["name"] = "default:leaves", ["z"] = 4, ["param1"] = 14}, {["y"] = 11, ["x"] = 1, ["name"] = "default:leaves", ["z"] = 3, ["param1"] = 14}, {["y"] = 11, ["x"] = 1, ["name"] = "default:leaves", ["z"] = 4, ["param1"] = 14}, {["y"] = 1, ["x"] = 2, ["name"] = "default:dirt", ["z"] = 3}, {["y"] = 2, ["x"] = 2, ["name"] = "default:dirt", ["z"] = 2}, {["y"] = 2, ["x"] = 2, ["name"] = "default:dirt", ["z"] = 3}, {["y"] = 2, ["x"] = 2, ["name"] = "default:dirt", ["z"] = 4}, {["y"] = 3, ["x"] = 2, ["name"] = "default:dirt", ["z"] = 1}, {["y"] = 3, ["x"] = 2, ["name"] = "default:dirt", ["z"] = 2}, {["y"] = 3, ["x"] = 2, ["name"] = "default:dirt", ["z"] = 3}, {["y"] = 3, ["x"] = 2, ["name"] = "default:dirt", ["z"] = 4}, {["y"] = 3, ["x"] = 2, ["name"] = "default:dirt", ["z"] = 5}, {["y"] = 4, ["x"] = 2, ["name"] = "default:dirt_with_grass", ["z"] = 0}, {["y"] = 4, ["x"] = 2, ["name"] = "default:dirt_with_grass", ["z"] = 1}, {["y"] = 4, ["x"] = 2, ["name"] = "default:dirt_with_grass", ["z"] = 2}, {["y"] = 4, ["x"] = 2, ["name"] = "default:dirt_with_grass", ["z"] = 3}, {["y"] = 4, ["x"] = 2, ["name"] = "default:dirt_with_grass", ["z"] = 4}, {["y"] = 4, ["x"] = 2, ["name"] = "default:dirt_with_grass", ["z"] = 5}, {["y"] = 4, ["x"] = 2, ["name"] = "default:dirt_with_grass", ["z"] = 6}, {["y"] = 8, ["x"] = 2, ["name"] = "default:leaves", ["z"] = 2, ["param1"] = 13}, {["y"] = 8, ["x"] = 2, ["name"] = "default:leaves", ["z"] = 3, ["param1"] = 13}, {["y"] = 8, ["x"] = 2, ["name"] = "default:leaves", ["z"] = 4, ["param1"] = 14}, {["y"] = 9, ["x"] = 2, ["name"] = "default:leaves", ["z"] = 1, ["param1"] = 14}, {["y"] = 9, ["x"] = 2, ["name"] = "default:leaves", ["z"] = 2, ["param1"] = 13}, {["y"] = 9, ["x"] = 2, ["name"] = "default:leaves", ["z"] = 3, ["param1"] = 13}, {["y"] = 9, ["x"] = 2, ["name"] = "default:leaves", ["z"] = 4, ["param1"] = 14}, {["y"] = 10, ["x"] = 2, ["name"] = "default:leaves", ["z"] = 1, ["param1"] = 14}, {["y"] = 10, ["x"] = 2, ["name"] = "default:leaves", ["z"] = 2, ["param1"] = 13}, {["y"] = 10, ["x"] = 2, ["name"] = "default:leaves", ["z"] = 3, ["param1"] = 13}, {["y"] = 10, ["x"] = 2, ["name"] = "default:leaves", ["z"] = 4, ["param1"] = 14}, {["y"] = 11, ["x"] = 2, ["name"] = "default:leaves", ["z"] = 2, ["param1"] = 14}, {["y"] = 11, ["x"] = 2, ["name"] = "default:leaves", ["z"] = 3, ["param1"] = 14}, {["y"] = 11, ["x"] = 2, ["name"] = "default:leaves", ["z"] = 4, ["param1"] = 14}, {["y"] = 0, ["x"] = 3, ["name"] = "default:dirt", ["z"] = 3}, {["y"] = 1, ["x"] = 3, ["name"] = "default:dirt", ["z"] = 2}, {["y"] = 1, ["x"] = 3, ["name"] = "default:dirt", ["z"] = 3}, {["y"] = 1, ["x"] = 3, ["name"] = "default:dirt", ["z"] = 4}, {["y"] = 2, ["x"] = 3, ["name"] = "default:dirt", ["z"] = 1}, {["y"] = 2, ["x"] = 3, ["name"] = "default:dirt", ["z"] = 2}, {["y"] = 2, ["x"] = 3, ["name"] = "default:dirt", ["z"] = 3}, {["y"] = 2, ["x"] = 3, ["name"] = "default:dirt", ["z"] = 4}, {["y"] = 2, ["x"] = 3, ["name"] = "default:dirt", ["z"] = 5}, {["y"] = 3, ["x"] = 3, ["name"] = "default:dirt", ["z"] = 0}, {["y"] = 3, ["x"] = 3, ["name"] = "default:dirt", ["z"] = 1}, {["y"] = 3, ["x"] = 3, ["name"] = "default:dirt", ["z"] = 2}, {["y"] = 3, ["x"] = 3, ["name"] = "default:dirt", ["z"] = 3}, {["y"] = 3, ["x"] = 3, ["name"] = "default:dirt", ["z"] = 4}, {["y"] = 3, ["x"] = 3, ["name"] = "default:dirt", ["z"] = 5}, {["y"] = 3, ["x"] = 3, ["name"] = "default:dirt", ["z"] = 6}, {["y"] = 4, ["x"] = 3, ["name"] = "default:dirt_with_grass", ["z"] = 0}, {["y"] = 4, ["x"] = 3, ["name"] = "default:dirt_with_grass", ["z"] = 1}, {["y"] = 4, ["x"] = 3, ["name"] = "default:dirt_with_grass", ["z"] = 2}, {["y"] = 4, ["x"] = 3, ["name"] = "default:dirt", ["z"] = 3}, {["y"] = 4, ["x"] = 3, ["name"] = "default:dirt_with_grass", ["z"] = 4}, {["y"] = 4, ["x"] = 3, ["name"] = "default:dirt_with_grass", ["z"] = 5}, {["y"] = 4, ["x"] = 3, ["name"] = "default:dirt_with_grass", ["z"] = 6}, {["y"] = 5, ["x"] = 3, ["name"] = "default:tree", ["z"] = 3, ["param1"] = 14}, {["y"] = 6, ["x"] = 3, ["name"] = "default:tree", ["z"] = 3, ["param1"] = 14}, {["y"] = 7, ["x"] = 3, ["name"] = "default:tree", ["z"] = 3, ["param1"] = 14}, {["y"] = 8, ["x"] = 3, ["name"] = "default:leaves", ["z"] = 1, ["param1"] = 14}, {["y"] = 8, ["x"] = 3, ["name"] = "default:leaves", ["z"] = 2, ["param1"] = 13}, {["y"] = 8, ["x"] = 3, ["name"] = "default:tree", ["z"] = 3, ["param1"] = 14}, {["y"] = 8, ["x"] = 3, ["name"] = "default:leaves", ["z"] = 4, ["param1"] = 14}, {["y"] = 9, ["x"] = 3, ["name"] = "default:leaves", ["z"] = 1, ["param1"] = 14}, {["y"] = 9, ["x"] = 3, ["name"] = "default:leaves", ["z"] = 2, ["param1"] = 13}, {["y"] = 9, ["x"] = 3, ["name"] = "default:tree", ["z"] = 3, ["param1"] = 14}, {["y"] = 9, ["x"] = 3, ["name"] = "default:leaves", ["z"] = 4, ["param1"] = 14}, {["y"] = 10, ["x"] = 3, ["name"] = "default:leaves", ["z"] = 1, ["param1"] = 14}, {["y"] = 10, ["x"] = 3, ["name"] = "default:leaves", ["z"] = 2, ["param1"] = 13}, {["y"] = 10, ["x"] = 3, ["name"] = "default:leaves", ["z"] = 3, ["param1"] = 13}, {["y"] = 10, ["x"] = 3, ["name"] = "default:leaves", ["z"] = 4, ["param1"] = 14}, {["y"] = 11, ["x"] = 3, ["name"] = "default:leaves", ["z"] = 1, ["param1"] = 14}, {["y"] = 11, ["x"] = 3, ["name"] = "default:leaves", ["z"] = 2, ["param1"] = 14}, {["y"] = 11, ["x"] = 3, ["name"] = "default:leaves", ["z"] = 3, ["param1"] = 14}, {["y"] = 11, ["x"] = 3, ["name"] = "default:leaves", ["z"] = 4, ["param1"] = 14}, {["y"] = 1, ["x"] = 4, ["name"] = "default:dirt", ["z"] = 3}, {["y"] = 2, ["x"] = 4, ["name"] = "default:dirt", ["z"] = 2}, {["y"] = 2, ["x"] = 4, ["name"] = "default:dirt", ["z"] = 3}, {["y"] = 2, ["x"] = 4, ["name"] = "default:dirt", ["z"] = 4}, {["y"] = 3, ["x"] = 4, ["name"] = "default:dirt", ["z"] = 1}, {["y"] = 3, ["x"] = 4, ["name"] = "default:dirt", ["z"] = 2}, {["y"] = 3, ["x"] = 4, ["name"] = "default:dirt", ["z"] = 3}, {["y"] = 3, ["x"] = 4, ["name"] = "default:dirt", ["z"] = 4}, {["y"] = 3, ["x"] = 4, ["name"] = "default:dirt", ["z"] = 5}, {["y"] = 4, ["x"] = 4, ["name"] = "default:dirt_with_grass", ["z"] = 0}, {["y"] = 4, ["x"] = 4, ["name"] = "default:dirt_with_grass", ["z"] = 1}, {["y"] = 4, ["x"] = 4, ["name"] = "default:dirt_with_grass", ["z"] = 2}, {["y"] = 4, ["x"] = 4, ["name"] = "default:dirt_with_grass", ["z"] = 3}, {["y"] = 4, ["x"] = 4, ["name"] = "default:dirt_with_grass", ["z"] = 4}, {["y"] = 4, ["x"] = 4, ["name"] = "default:dirt_with_grass", ["z"] = 5}, {["y"] = 4, ["x"] = 4, ["name"] = "default:dirt_with_grass", ["z"] = 6}, {["y"] = 8, ["x"] = 4, ["name"] = "default:leaves", ["z"] = 1, ["param1"] = 14}, {["y"] = 8, ["x"] = 4, ["name"] = "default:leaves", ["z"] = 2, ["param1"] = 13}, {["y"] = 8, ["x"] = 4, ["name"] = "default:leaves", ["z"] = 3, ["param1"] = 14}, {["y"] = 8, ["x"] = 4, ["name"] = "default:leaves", ["z"] = 4, ["param1"] = 14}, {["y"] = 9, ["x"] = 4, ["name"] = "default:leaves", ["z"] = 1, ["param1"] = 14}, {["y"] = 9, ["x"] = 4, ["name"] = "default:leaves", ["z"] = 2, ["param1"] = 13}, {["y"] = 9, ["x"] = 4, ["name"] = "default:leaves", ["z"] = 3, ["param1"] = 14}, {["y"] = 9, ["x"] = 4, ["name"] = "default:leaves", ["z"] = 4, ["param1"] = 14}, {["y"] = 10, ["x"] = 4, ["name"] = "default:leaves", ["z"] = 1, ["param1"] = 14}, {["y"] = 10, ["x"] = 4, ["name"] = "default:leaves", ["z"] = 2, ["param1"] = 13}, {["y"] = 10, ["x"] = 4, ["name"] = "default:leaves", ["z"] = 3, ["param1"] = 14}, {["y"] = 10, ["x"] = 4, ["name"] = "default:leaves", ["z"] = 4, ["param1"] = 14}, {["y"] = 11, ["x"] = 4, ["name"] = "default:leaves", ["z"] = 1, ["param1"] = 14}, {["y"] = 11, ["x"] = 4, ["name"] = "default:leaves", ["z"] = 2, ["param1"] = 14}, {["y"] = 11, ["x"] = 4, ["name"] = "default:leaves", ["z"] = 3, ["param1"] = 14}, {["y"] = 11, ["x"] = 4, ["name"] = "default:leaves", ["z"] = 4, ["param1"] = 14}, {["y"] = 2, ["x"] = 5, ["name"] = "default:dirt", ["z"] = 3}, {["y"] = 3, ["x"] = 5, ["name"] = "default:dirt", ["z"] = 1}, {["y"] = 3, ["x"] = 5, ["name"] = "default:dirt", ["z"] = 2}, {["y"] = 3, ["x"] = 5, ["name"] = "default:dirt", ["z"] = 3}, {["y"] = 3, ["x"] = 5, ["name"] = "default:dirt", ["z"] = 4}, {["y"] = 3, ["x"] = 5, ["name"] = "default:dirt", ["z"] = 5}, {["y"] = 4, ["x"] = 5, ["name"] = "default:dirt_with_grass", ["z"] = 0}, {["y"] = 4, ["x"] = 5, ["name"] = "default:dirt_with_grass", ["z"] = 1}, {["y"] = 4, ["x"] = 5, ["name"] = "default:dirt_with_grass", ["z"] = 2}, {["y"] = 4, ["x"] = 5, ["name"] = "default:dirt_with_grass", ["z"] = 3}, {["y"] = 4, ["x"] = 5, ["name"] = "default:dirt_with_grass", ["z"] = 4}, {["y"] = 4, ["x"] = 5, ["name"] = "default:dirt_with_grass", ["z"] = 5}, {["y"] = 4, ["x"] = 5, ["name"] = "default:dirt_with_grass", ["z"] = 6}, {["y"] = 5, ["x"] = 5, ["name"] = "default:chest", ["z"] = 2, ["meta"] = {["inventory"] = {["main"] = {"bucket:bucket_water", "bucket:bucket_water", "bucket:bucket_lava", "default:papyrus 5", "default:cactus 3", "flowers:mushroom_red", "flowers:mushroom_brown", "default:sand_with_kelp 7", "", "", "", "", "", "", "", "", "", "", "", "", "", "", "", "", "", "", "", "", "", "", "", ""}}, ["fields"] = {["infotext"] = "(T@default)ChestE"}}, ["param2"] = 2, ["param1"] = 14}, {["y"] = 10, ["x"] = 5, ["name"] = "default:leaves", ["z"] = 1, ["param1"] = 14}, {["y"] = 10, ["x"] = 5, ["name"] = "default:leaves", ["z"] = 2, ["param1"] = 14}, {["y"] = 11, ["x"] = 5, ["name"] = "default:leaves", ["z"] = 1, ["param1"] = 14}, {["y"] = 11, ["x"] = 5, ["name"] = "default:leaves", ["z"] = 2, ["param1"] = 14}, {["y"] = 3, ["x"] = 6, ["name"] = "default:dirt", ["z"] = 3}, {["y"] = 4, ["x"] = 6, ["name"] = "default:dirt_with_grass", ["z"] = 1}, {["y"] = 4, ["x"] = 6, ["name"] = "default:dirt_with_grass", ["z"] = 2}, {["y"] = 4, ["x"] = 6, ["name"] = "default:dirt_with_grass", ["z"] = 3}, {["y"] = 4, ["x"] = 6, ["name"] = "default:dirt_with_grass", ["z"] = 4}, {["y"] = 4, ["x"] = 6, ["name"] = "default:dirt_with_grass", ["z"] = 5}}